Workbook
Name MovieRange: Data!$A$1:$N$1077
Name NativeTimeline_Release_Date: #N/A
Name Slicer_Country: #N/A

Sheet Pivot Table
A2: Slicer to filter Pivot 1 table by Country Wise | L2: Timeline to filter Pivot 2 table by Time Series
V12: Top 20 Movies with Highest Budget
A13: Pivot 1 | L13: Pivot 2
A14: Language | B14: Genre | C14: Budget | D14: Box Office | E14: Profit | F14: Oscar Wins | G14: Nominations | H14: Run Time (Min. | L14: Row Labels | M14: Budget | N14: Box Office | O14: Profit | P14: Oscar Wins | Q14: Nominations | R14: Run Time (Min. | V14: Title | W14: Budget | X14: Box Office | Y14: Profit | Z14: Oscar Wins | AA14: Nominations | AB14: Run Time (Min.
A15: Cantonese | B15: Martial Arts | C15: 110965000 | D15: 408736047 | E15: 297771047 | F15: 0 | G15: 0 | H15: 1010 | L15: 1931 | M15: 768000 | N15: 12506000 | O15: 11738000 | P15: 0 | Q15: 1 | R15: 239 | V15: Dracula | W15: 355000 | X15: 355000 | Y15: 0 | Z15: 0 | AA15: 0 | AB15: 85
B16: Action | C16: 4500000 | D16: 4500000 | E16: 0 | F16: 0 | G16: 0 | H16: 128 | L16: 11366 | M16: 355000 | N16: 355000 | O16: 0 | P16: 0 | Q16: 0 | R16: 85 | V16: Frankenstein | W16: 262000 | X16: 12000000 | Y16: 11738000 | Z16: 0 | AA16: 0 | AB16: 71
A17: Cantonese Total | C17: 115465000 | D17: 413236047 | E17: 297771047 | F17: 0 | G17: 0 | H17: 1138 | L17: 11436 | M17: 151000 | N17: 151000 | O17: 0 | P17: 0 | Q17: 1 | R17: 83 | V17: The Public Enemy | W17: 151000 | X17: 151000 | Y17: 0 | Z17: 0 | AA17: 1 | AB17: 83
A18: Mandarin | B18: War | C18: 40000000 | D18: 40000000 | E18: 0 | F18: 0 | G18: 0 | H18: 127 | L18: 11648 | M18: 262000 | N18: 12000000 | O18: 11738000 | P18: 0 | Q18: 0 | R18: 71 | V18: Grand Total | W18: 768000 | X18: 12506000 | Y18: 11738000 | Z18: 0 | AA18: 1 | AB18: 239
B19: Martial Arts | C19: 38230000 | D19: 55700000 | E19: 17470000 | F19: 0 | G19: 0 | H19: 477 | L19: Grand Total | M19: 768000 | N19: 12506000 | O19: 11738000 | P19: 0 | Q19: 1 | R19: 239
A20: Mandarin Total | C20: 78230000 | D20: 95700000 | E20: 17470000 | F20: 0 | G20: 0 | H20: 604
A21: English | B21: Martial Arts | C21: 850000 | D21: 22000000 | E21: 21150000 | F21: 0 | G21: 0 | H21: 102
A22: English Total | C22: 850000 | D22: 22000000 | E22: 21150000 | F22: 0 | G22: 0 | H22: 102
A23: Grand Total | C23: 194545000 | D23: 530936047 | E23: 336391047 | F23: 0 | G23: 0 | H23: 1844
V39: Top 20 Movies by Highest Profit
V41: Title | W41: Budget | X41: Box Office | Y41: Profit | Z41: Oscar Wins | AA41: Nominations | AB41: Run Time (Min.
V42: Frankenstein | W42: 262000 | X42: 12000000 | Y42: 11738000 | Z42: 0 | AA42: 0 | AB42: 71
V43: The Public Enemy | W43: 151000 | X43: 151000 | Y43: 0 | Z43: 0 | AA43: 1 | AB43: 83
V44: Dracula | W44: 355000 | X44: 355000 | Y44: 0 | Z44: 0 | AA44: 0 | AB44: 85
V45: Grand Total | W45: 768000 | X45: 12506000 | Y45: 11738000 | Z45: 0 | AA45: 1 | AB45: 239
V65: Year wise Movies Count
V67: Years (Release Date) | W67: Movies Releases | X67: Budget | Y67: Box Office | Z67: Profit | AA67: Oscar Wins | AB67: Nominations | AC67: Run Time (Min.
V68: 1931 | W68: 3 | X68: 768000 | Y68: 12506000 | Z68: 11738000 | AA68: 0 | AB68: 1 | AC68: 239
V69: Grand Total | W69: 3 | X69: 768000 | Y69: 12506000 | Z69: 11738000 | AA69: 0 | AB69: 1 | AC69: 239
V157: Movies With Most Oscars Wins
V159: Title | W159: Years (Release Date) | X159: Budget | Y159: Box Office | Z159: Profit | AA159: Oscar Wins | AB159: Nominations | AC159: Run Time (Min.
V160: Grand Total

Sheet Vlookup
A1: DETAILS OF MOVIES WHO WON MORE THAN 5 OSCARS
A3: Movie Name | B3: Release Date | C3: Run Time | D3: Genre | E3: Director | F3: Studio | G3: Country | H3: Language | I3: Certificate | J3: Budget | K3: Box Office | L3: Nominations | M3: Oscar Wins | U3: Title
A4: Titanic | B4: =VLOOKUP($A4,Table1[[#All],[Title]:[Oscar Wins]],COLUMNS($A$3:B3),0) -> 35818 | C4: =VLOOKUP($A4,Table1[[#All],[Title]:[Oscar Wins]],COLUMNS($A$3:C3),0) -> 194 | D4: =VLOOKUP($A4,Table1[[#All],[Title]:[Oscar Wins]],COLUMNS($A$3:D3),0) -> Romance | E4: =VLOOKUP($A4,Table1[[#All],[Title]:[Oscar Wins]],COLUMNS($A$3:E3),0) -> James Cameron | F4: =VLOOKUP($A4,Table1[[#All],[Title]:[Oscar Wins]],COLUMNS($A$3:F3),0) -> 20th Century Fox | G4: =VLOOKUP($A4,Table1[[#All],[Title]:[Oscar Wins]],COLUMNS($A$3:G3),0) -> United States | H4: =VLOOKUP($A4,Table1[[#All],[Title]:[Oscar Wins]],COLUMNS($A$3:H3),0) -> English | I4: =VLOOKUP($A4,Table1[[#All],[Title]:[Oscar Wins]],COLUMNS($A$3:I3),0) -> 12 | J4: =ROUND(VLOOKUP($A4,Table1[[#All],[Title]:[Oscar Wins]],COLUMNS($A$3:J3),0)/1000000,2)&" M" -> 200 M | K4: =ROUND(VLOOKUP($A4,Table1[[#All],[Title]:[Oscar Wins]],COLUMNS($A$3:K3),0)/1000000,2)&" M" -> 2186.77 M | L4: =VLOOKUP($A4,Table1[[#All],[Title]:[Oscar Wins]],COLUMNS($A$3:L3),0) -> 14 | M4: =VLOOKUP($A4,Table1[[#All],[Title]:[Oscar Wins]],COLUMNS($A$3:M3),0) -> 11 | U4: 10
A5: The Lord of the Rings: Return of the King | B5: =VLOOKUP($A5,Table1[[#All],[Title]:[Oscar Wins]],COLUMNS($A$3:B4),0) -> 37972 | C5: =VLOOKUP($A5,Table1[[#All],[Title]:[Oscar Wins]],COLUMNS($A$3:C4),0) -> 201 | D5: =VLOOKUP($A5,Table1[[#All],[Title]:[Oscar Wins]],COLUMNS($A$3:D4),0) -> Fantasy | E5: =VLOOKUP($A5,Table1[[#All],[Title]:[Oscar Wins]],COLUMNS($A$3:E4),0) -> Peter Jackson | F5: =VLOOKUP($A5,Table1[[#All],[Title]:[Oscar Wins]],COLUMNS($A$3:F4),0) -> WingNut Films | G5: =VLOOKUP($A5,Table1[[#All],[Title]:[Oscar Wins]],COLUMNS($A$3:G4),0) -> New Zealand | H5: =VLOOKUP($A5,Table1[[#All],[Title]:[Oscar Wins]],COLUMNS($A$3:H4),0) -> English | I5: =VLOOKUP($A5,Table1[[#All],[Title]:[Oscar Wins]],COLUMNS($A$3:I4),0) -> 12A | J5: =ROUND(VLOOKUP($A5,Table1[[#All],[Title]:[Oscar Wins]],COLUMNS($A$3:J4),0)/1000000,2)&" M" -> 94 M | K5: =ROUND(VLOOKUP($A5,Table1[[#All],[Title]:[Oscar Wins]],COLUMNS($A$3:K4),0)/1000000,2)&" M" -> 1119.93 M | L5: =VLOOKUP($A5,Table1[[#All],[Title]:[Oscar Wins]],COLUMNS($A$3:L4),0) -> 11 | M5: =VLOOKUP($A5,Table1[[#All],[Title]:[Oscar Wins]],COLUMNS($A$3:M4),0) -> 11 | U5: 300
A6: Ben-Hur | B6: =VLOOKUP($A6,Table1[[#All],[Title]:[Oscar Wins]],COLUMNS($A$3:B5),0) -> 21872 | C6: =VLOOKUP($A6,Table1[[#All],[Title]:[Oscar Wins]],COLUMNS($A$3:C5),0) -> 212 | D6: =VLOOKUP($A6,Table1[[#All],[Title]:[Oscar Wins]],COLUMNS($A$3:D5),0) -> Drama | E6: =VLOOKUP($A6,Table1[[#All],[Title]:[Oscar Wins]],COLUMNS($A$3:E5),0) -> William Wyler | F6: =VLOOKUP($A6,Table1[[#All],[Title]:[Oscar Wins]],COLUMNS($A$3:F5),0) -> Metro-Goldwyn-Mayer | G6: =VLOOKUP($A6,Table1[[#All],[Title]:[Oscar Wins]],COLUMNS($A$3:G5),0) -> United States | H6: =VLOOKUP($A6,Table1[[#All],[Title]:[Oscar Wins]],COLUMNS($A$3:H5),0) -> English | I6: =VLOOKUP($A6,Table1[[#All],[Title]:[Oscar Wins]],COLUMNS($A$3:I5),0) -> PG | J6: =ROUND(VLOOKUP($A6,Table1[[#All],[Title]:[Oscar Wins]],COLUMNS($A$3:J5),0)/1000000,2)&" M" -> 15.2 M | K6: =ROUND(VLOOKUP($A6,Table1[[#All],[Title]:[Oscar Wins]],COLUMNS($A$3:K5),0)/1000000,2)&" M" -> 146.9 M | L6: =VLOOKUP($A6,Table1[[#All],[Title]:[Oscar Wins]],COLUMNS($A$3:L5),0) -> 12 | M6: =VLOOKUP($A6,Table1[[#All],[Title]:[Oscar Wins]],COLUMNS($A$3:M5),0) -> 11 | U6: 2012
A7: West Side Story | B7: =VLOOKUP($A7,Table1[[#All],[Title]:[Oscar Wins]],COLUMNS($A$3:B6),0) -> 22572 | C7: =VLOOKUP($A7,Table1[[#All],[Title]:[Oscar Wins]],COLUMNS($A$3:C6),0) -> 152 | D7: =VLOOKUP($A7,Table1[[#All],[Title]:[Oscar Wins]],COLUMNS($A$3:D6),0) -> Musical | E7: =VLOOKUP($A7,Table1[[#All],[Title]:[Oscar Wins]],COLUMNS($A$3:E6),0) -> Robert Wise | F7: =VLOOKUP($A7,Table1[[#All],[Title]:[Oscar Wins]],COLUMNS($A$3:F6),0) -> The Mirisch Production Company | G7: =VLOOKUP($A7,Table1[[#All],[Title]:[Oscar Wins]],COLUMNS($A$3:G6),0) -> United States | H7: =VLOOKUP($A7,Table1[[#All],[Title]:[Oscar Wins]],COLUMNS($A$3:H6),0) -> English | I7: =VLOOKUP($A7,Table1[[#All],[Title]:[Oscar Wins]],COLUMNS($A$3:I6),0) -> PG | J7: =ROUND(VLOOKUP($A7,Table1[[#All],[Title]:[Oscar Wins]],COLUMNS($A$3:J6),0)/1000000,2)&" M" -> 6 M | K7: =ROUND(VLOOKUP($A7,Table1[[#All],[Title]:[Oscar Wins]],COLUMNS($A$3:K6),0)/1000000,2)&" M" -> 43.7 M | L7: =VLOOKUP($A7,Table1[[#All],[Title]:[Oscar Wins]],COLUMNS($A$3:L6),0) -> 11 | M7: =VLOOKUP($A7,Table1[[#All],[Title]:[Oscar Wins]],COLUMNS($A$3:M6),0) -> 10 | U7: 101 Dalmatians
A8: The English Patient | B8: =VLOOKUP($A8,Table1[[#All],[Title]:[Oscar Wins]],COLUMNS($A$3:B7),0) -> 35384 | C8: =VLOOKUP($A8,Table1[[#All],[Title]:[Oscar Wins]],COLUMNS($A$3:C7),0) -> 162 | D8: =VLOOKUP($A8,Table1[[#All],[Title]:[Oscar Wins]],COLUMNS($A$3:D7),0) -> Romance | E8: =VLOOKUP($A8,Table1[[#All],[Title]:[Oscar Wins]],COLUMNS($A$3:E7),0) -> Anthony Minghella | F8: =VLOOKUP($A8,Table1[[#All],[Title]:[Oscar Wins]],COLUMNS($A$3:F7),0) -> Miramax Films | G8: =VLOOKUP($A8,Table1[[#All],[Title]:[Oscar Wins]],COLUMNS($A$3:G7),0) -> United Kingdom | H8: =VLOOKUP($A8,Table1[[#All],[Title]:[Oscar Wins]],COLUMNS($A$3:H7),0) -> English | I8: =VLOOKUP($A8,Table1[[#All],[Title]:[Oscar Wins]],COLUMNS($A$3:I7),0) -> 15 | J8: =ROUND(VLOOKUP($A8,Table1[[#All],[Title]:[Oscar Wins]],COLUMNS($A$3:J7),0)/1000000,2)&" M" -> 27 M | K8: =ROUND(VLOOKUP($A8,Table1[[#All],[Title]:[Oscar Wins]],COLUMNS($A$3:K7),0)/1000000,2)&" M" -> 232 M | L8: =VLOOKUP($A8,Table1[[#All],[Title]:[Oscar Wins]],COLUMNS($A$3:L7),0) -> 12 | M8: =VLOOKUP($A8,Table1[[#All],[Title]:[Oscar Wins]],COLUMNS($A$3:M7),0) -> 9 | U8: 12 Years a Slave
A9: On the Waterfront | B9: =VLOOKUP($A9,Table1[[#All],[Title]:[Oscar Wins]],COLUMNS($A$3:B8),0) -> 19933 | C9: =VLOOKUP($A9,Table1[[#All],[Title]:[Oscar Wins]],COLUMNS($A$3:C8),0) -> 108 | D9: =VLOOKUP($A9,Table1[[#All],[Title]:[Oscar Wins]],COLUMNS($A$3:D8),0) -> Crime | E9: =VLOOKUP($A9,Table1[[#All],[Title]:[Oscar Wins]],COLUMNS($A$3:E8),0) -> Elia Kazan | F9: =VLOOKUP($A9,Table1[[#All],[Title]:[Oscar Wins]],COLUMNS($A$3:F8),0) -> Horizon Pictures | G9: =VLOOKUP($A9,Table1[[#All],[Title]:[Oscar Wins]],COLUMNS($A$3:G8),0) -> United States | H9: =VLOOKUP($A9,Table1[[#All],[Title]:[Oscar Wins]],COLUMNS($A$3:H8),0) -> English | I9: =VLOOKUP($A9,Table1[[#All],[Title]:[Oscar Wins]],COLUMNS($A$3:I8),0) -> PG | J9: =ROUND(VLOOKUP($A9,Table1[[#All],[Title]:[Oscar Wins]],COLUMNS($A$3:J8),0)/1000000,2)&" M" -> 0.91 M | K9: =ROUND(VLOOKUP($A9,Table1[[#All],[Title]:[Oscar Wins]],COLUMNS($A$3:K8),0)/1000000,2)&" M" -> 9.6 M | L9: =VLOOKUP($A9,Table1[[#All],[Title]:[Oscar Wins]],COLUMNS($A$3:L8),0) -> 12 | M9: =VLOOKUP($A9,Table1[[#All],[Title]:[Oscar Wins]],COLUMNS($A$3:M8),0) -> 8 | U9: 127 Hours
A10: Gone with the Wind | B10: =VLOOKUP($A10,Table1[[#All],[Title]:[Oscar Wins]],COLUMNS($A$3:B9),0) -> 14594 | C10: =VLOOKUP($A10,Table1[[#All],[Title]:[Oscar Wins]],COLUMNS($A$3:C9),0) -> 221 | D10: =VLOOKUP($A10,Table1[[#All],[Title]:[Oscar Wins]],COLUMNS($A$3:D9),0) -> Romance | E10: =VLOOKUP($A10,Table1[[#All],[Title]:[Oscar Wins]],COLUMNS($A$3:E9),0) -> Victor Fleming | F10: =VLOOKUP($A10,Table1[[#All],[Title]:[Oscar Wins]],COLUMNS($A$3:F9),0) -> Selznick International Pictures | G10: =VLOOKUP($A10,Table1[[#All],[Title]:[Oscar Wins]],COLUMNS($A$3:G9),0) -> United States | H10: =VLOOKUP($A10,Table1[[#All],[Title]:[Oscar Wins]],COLUMNS($A$3:H9),0) -> English | I10: =VLOOKUP($A10,Table1[[#All],[Title]:[Oscar Wins]],COLUMNS($A$3:I9),0) -> PG | J10: =ROUND(VLOOKUP($A10,Table1[[#All],[Title]:[Oscar Wins]],COLUMNS($A$3:J9),0)/1000000,2)&" M" -> 3.85 M | K10: =ROUND(VLOOKUP($A10,Table1[[#All],[Title]:[Oscar Wins]],COLUMNS($A$3:K9),0)/1000000,2)&" M" -> 198 M | L10: =VLOOKUP($A10,Table1[[#All],[Title]:[Oscar Wins]],COLUMNS($A$3:L9),0) -> 13 | M10: =VLOOKUP($A10,Table1[[#All],[Title]:[Oscar Wins]],COLUMNS($A$3:M9),0) -> 8 | U10: 13 Assassins
A11: Cabaret | B11: =VLOOKUP($A11,Table1[[#All],[Title]:[Oscar Wins]],COLUMNS($A$3:B10),0) -> 26342 | C11: =VLOOKUP($A11,Table1[[#All],[Title]:[Oscar Wins]],COLUMNS($A$3:C10),0) -> 124 | D11: =VLOOKUP($A11,Table1[[#All],[Title]:[Oscar Wins]],COLUMNS($A$3:D10),0) -> Musical | E11: =VLOOKUP($A11,Table1[[#All],[Title]:[Oscar Wins]],COLUMNS($A$3:E10),0) -> Bob Fosse | F11: =VLOOKUP($A11,Table1[[#All],[Title]:[Oscar Wins]],COLUMNS($A$3:F10),0) -> Allied Artists | G11: =VLOOKUP($A11,Table1[[#All],[Title]:[Oscar Wins]],COLUMNS($A$3:G10),0) -> United States | H11: =VLOOKUP($A11,Table1[[#All],[Title]:[Oscar Wins]],COLUMNS($A$3:H10),0) -> English | I11: =VLOOKUP($A11,Table1[[#All],[Title]:[Oscar Wins]],COLUMNS($A$3:I10),0) -> 15 | J11: =ROUND(VLOOKUP($A11,Table1[[#All],[Title]:[Oscar Wins]],COLUMNS($A$3:J10),0)/1000000,2)&" M" -> 2.29 M | K11: =ROUND(VLOOKUP($A11,Table1[[#All],[Title]:[Oscar Wins]],COLUMNS($A$3:K10),0)/1000000,2)&" M" -> 42.77 M | L11: =VLOOKUP($A11,Table1[[#All],[Title]:[Oscar Wins]],COLUMNS($A$3:L10),0) -> 10 | M11: =VLOOKUP($A11,Table1[[#All],[Title]:[Oscar Wins]],COLUMNS($A$3:M10),0) -> 8 | U11: 1492: Conquest of Paradise
A12: Slumdog Millionaire | B12: =VLOOKUP($A12,Table1[[#All],[Title]:[Oscar Wins]],COLUMNS($A$3:B11),0) -> 39690 | C12: =VLOOKUP($A12,Table1[[#All],[Title]:[Oscar Wins]],COLUMNS($A$3:C11),0) -> 120 | D12: =VLOOKUP($A12,Table1[[#All],[Title]:[Oscar Wins]],COLUMNS($A$3:D11),0) -> Drama | E12: =VLOOKUP($A12,Table1[[#All],[Title]:[Oscar Wins]],COLUMNS($A$3:E11),0) -> Danny Boyle | F12: =VLOOKUP($A12,Table1[[#All],[Title]:[Oscar Wins]],COLUMNS($A$3:F11),0) -> FilmFour Productions | G12: =VLOOKUP($A12,Table1[[#All],[Title]:[Oscar Wins]],COLUMNS($A$3:G11),0) -> United Kingdom | H12: =VLOOKUP($A12,Table1[[#All],[Title]:[Oscar Wins]],COLUMNS($A$3:H11),0) -> English | I12: =VLOOKUP($A12,Table1[[#All],[Title]:[Oscar Wins]],COLUMNS($A$3:I11),0) -> 15 | J12: =ROUND(VLOOKUP($A12,Table1[[#All],[Title]:[Oscar Wins]],COLUMNS($A$3:J11),0)/1000000,2)&" M" -> 15 M | K12: =ROUND(VLOOKUP($A12,Table1[[#All],[Title]:[Oscar Wins]],COLUMNS($A$3:K11),0)/1000000,2)&" M" -> 377.9 M | L12: =VLOOKUP($A12,Table1[[#All],[Title]:[Oscar Wins]],COLUMNS($A$3:L11),0) -> 10 | M12: =VLOOKUP($A12,Table1[[#All],[Title]:[Oscar Wins]],COLUMNS($A$3:M11),0) -> 8 | U12: 20,000 Leagues Under the Sea
A13: From Here to Eternity | B13: =VLOOKUP($A13,Table1[[#All],[Title]:[Oscar Wins]],COLUMNS($A$3:B12),0) -> 19576 | C13: =VLOOKUP($A13,Table1[[#All],[Title]:[Oscar Wins]],COLUMNS($A$3:C12),0) -> 118 | D13: =VLOOKUP($A13,Table1[[#All],[Title]:[Oscar Wins]],COLUMNS($A$3:D12),0) -> Drama | E13: =VLOOKUP($A13,Table1[[#All],[Title]:[Oscar Wins]],COLUMNS($A$3:E12),0) -> Fred Zinnemann | F13: =VLOOKUP($A13,Table1[[#All],[Title]:[Oscar Wins]],COLUMNS($A$3:F12),0) -> Columbia Pictures | G13: =VLOOKUP($A13,Table1[[#All],[Title]:[Oscar Wins]],COLUMNS($A$3:G12),0) -> United States | H13: =VLOOKUP($A13,Table1[[#All],[Title]:[Oscar Wins]],COLUMNS($A$3:H12),0) -> English | I13: =VLOOKUP($A13,Table1[[#All],[Title]:[Oscar Wins]],COLUMNS($A$3:I12),0) -> PG | J13: =ROUND(VLOOKUP($A13,Table1[[#All],[Title]:[Oscar Wins]],COLUMNS($A$3:J12),0)/1000000,2)&" M" -> 2.5 M | K13: =ROUND(VLOOKUP($A13,Table1[[#All],[Title]:[Oscar Wins]],COLUMNS($A$3:K12),0)/1000000,2)&" M" -> 30.5 M | L13: =VLOOKUP($A13,Table1[[#All],[Title]:[Oscar Wins]],COLUMNS($A$3:L12),0) -> 13 | M13: =VLOOKUP($A13,Table1[[#All],[Title]:[Oscar Wins]],COLUMNS($A$3:M12),0) -> 8 | U13: 2001: A Space Odyssey
A14: Gandhi | B14: =VLOOKUP($A14,Table1[[#All],[Title]:[Oscar Wins]],COLUMNS($A$3:B13),0) -> 30287 | C14: =VLOOKUP($A14,Table1[[#All],[Title]:[Oscar Wins]],COLUMNS($A$3:C13),0) -> 188 | D14: =VLOOKUP($A14,Table1[[#All],[Title]:[Oscar Wins]],COLUMNS($A$3:D13),0) -> Biography | E14: =VLOOKUP($A14,Table1[[#All],[Title]:[Oscar Wins]],COLUMNS($A$3:E13),0) -> Richard Attenborough | F14: =VLOOKUP($A14,Table1[[#All],[Title]:[Oscar Wins]],COLUMNS($A$3:F13),0) -> Goldcrest Films | G14: =VLOOKUP($A14,Table1[[#All],[Title]:[Oscar Wins]],COLUMNS($A$3:G13),0) -> United Kingdom | H14: =VLOOKUP($A14,Table1[[#All],[Title]:[Oscar Wins]],COLUMNS($A$3:H13),0) -> English | I14: =VLOOKUP($A14,Table1[[#All],[Title]:[Oscar Wins]],COLUMNS($A$3:I13),0) -> PG | J14: =ROUND(VLOOKUP($A14,Table1[[#All],[Title]:[Oscar Wins]],COLUMNS($A$3:J13),0)/1000000,2)&" M" -> 22 M | K14: =ROUND(VLOOKUP($A14,Table1[[#All],[Title]:[Oscar Wins]],COLUMNS($A$3:K13),0)/1000000,2)&" M" -> 52.77 M | L14: =VLOOKUP($A14,Table1[[#All],[Title]:[Oscar Wins]],COLUMNS($A$3:L13),0) -> 11 | M14: =VLOOKUP($A14,Table1[[#All],[Title]:[Oscar Wins]],COLUMNS($A$3:M13),0) -> 8 | U14: 21 Grams
A15: My Fair Lady | B15: =VLOOKUP($A15,Table1[[#All],[Title]:[Oscar Wins]],COLUMNS($A$3:B14),0) -> 23690 | C15: =VLOOKUP($A15,Table1[[#All],[Title]:[Oscar Wins]],COLUMNS($A$3:C14),0) -> 170 | D15: =VLOOKUP($A15,Table1[[#All],[Title]:[Oscar Wins]],COLUMNS($A$3:D14),0) -> Musical | E15: =VLOOKUP($A15,Table1[[#All],[Title]:[Oscar Wins]],COLUMNS($A$3:E14),0) -> George Cukor | F15: =VLOOKUP($A15,Table1[[#All],[Title]:[Oscar Wins]],COLUMNS($A$3:F14),0) -> Warner Bros. Pictures | G15: =VLOOKUP($A15,Table1[[#All],[Title]:[Oscar Wins]],COLUMNS($A$3:G14),0) -> United States | H15: =VLOOKUP($A15,Table1[[#All],[Title]:[Oscar Wins]],COLUMNS($A$3:H14),0) -> English | I15: =VLOOKUP($A15,Table1[[#All],[Title]:[Oscar Wins]],COLUMNS($A$3:I14),0) -> U | J15: =ROUND(VLOOKUP($A15,Table1[[#All],[Title]:[Oscar Wins]],COLUMNS($A$3:J14),0)/1000000,2)&" M" -> 17 M | K15: =ROUND(VLOOKUP($A15,Table1[[#All],[Title]:[Oscar Wins]],COLUMNS($A$3:K14),0)/1000000,2)&" M" -> 72 M | L15: =VLOOKUP($A15,Table1[[#All],[Title]:[Oscar Wins]],COLUMNS($A$3:L14),0) -> 12 | M15: =VLOOKUP($A15,Table1[[#All],[Title]:[Oscar Wins]],COLUMNS($A$3:M14),0) -> 8 | U15: 21 Jump Street
A16: Shakespeare in Love | B16: =VLOOKUP($A16,Table1[[#All],[Title]:[Oscar Wins]],COLUMNS($A$3:B15),0) -> 36132 | C16: =VLOOKUP($A16,Table1[[#All],[Title]:[Oscar Wins]],COLUMNS($A$3:C15),0) -> 123 | D16: =VLOOKUP($A16,Table1[[#All],[Title]:[Oscar Wins]],COLUMNS($A$3:D15),0) -> Romantic Comedy | E16: =VLOOKUP($A16,Table1[[#All],[Title]:[Oscar Wins]],COLUMNS($A$3:E15),0) -> John Madden | F16: =VLOOKUP($A16,Table1[[#All],[Title]:[Oscar Wins]],COLUMNS($A$3:F15),0) -> The Bedford Falls Company | G16: =VLOOKUP($A16,Table1[[#All],[Title]:[Oscar Wins]],COLUMNS($A$3:G15),0) -> United Kingdom | H16: =VLOOKUP($A16,Table1[[#All],[Title]:[Oscar Wins]],COLUMNS($A$3:H15),0) -> English | I16: =VLOOKUP($A16,Table1[[#All],[Title]:[Oscar Wins]],COLUMNS($A$3:I15),0) -> 15 | J16: =ROUND(VLOOKUP($A16,Table1[[#All],[Title]:[Oscar Wins]],COLUMNS($A$3:J15),0)/1000000,2)&" M" -> 25 M | K16: =ROUND(VLOOKUP($A16,Table1[[#All],[Title]:[Oscar Wins]],COLUMNS($A$3:K15),0)/1000000,2)&" M" -> 289.3 M | L16: =VLOOKUP($A16,Table1[[#All],[Title]:[Oscar Wins]],COLUMNS($A$3:L15),0) -> 13 | M16: =VLOOKUP($A16,Table1[[#All],[Title]:[Oscar Wins]],COLUMNS($A$3:M15),0) -> 7 | U16: 22 Jump Street
A17: Patton | B17: =VLOOKUP($A17,Table1[[#All],[Title]:[Oscar Wins]],COLUMNS($A$3:B16),0) -> 25660 | C17: =VLOOKUP($A17,Table1[[#All],[Title]:[Oscar Wins]],COLUMNS($A$3:C16),0) -> 170 | D17: =VLOOKUP($A17,Table1[[#All],[Title]:[Oscar Wins]],COLUMNS($A$3:D16),0) -> Biography | E17: =VLOOKUP($A17,Table1[[#All],[Title]:[Oscar Wins]],COLUMNS($A$3:E16),0) -> Franklin J. Schaffner | F17: =VLOOKUP($A17,Table1[[#All],[Title]:[Oscar Wins]],COLUMNS($A$3:F16),0) -> 20th Century Fox | G17: =VLOOKUP($A17,Table1[[#All],[Title]:[Oscar Wins]],COLUMNS($A$3:G16),0) -> United States | H17: =VLOOKUP($A17,Table1[[#All],[Title]:[Oscar Wins]],COLUMNS($A$3:H16),0) -> English | I17: =VLOOKUP($A17,Table1[[#All],[Title]:[Oscar Wins]],COLUMNS($A$3:I16),0) -> PG | J17: =ROUND(VLOOKUP($A17,Table1[[#All],[Title]:[Oscar Wins]],COLUMNS($A$3:J16),0)/1000000,2)&" M" -> 12.6 M | K17: =ROUND(VLOOKUP($A17,Table1[[#All],[Title]:[Oscar Wins]],COLUMNS($A$3:K16),0)/1000000,2)&" M" -> 61.8 M | L17: =VLOOKUP($A17,Table1[[#All],[Title]:[Oscar Wins]],COLUMNS($A$3:L16),0) -> 10 | M17: =VLOOKUP($A17,Table1[[#All],[Title]:[Oscar Wins]],COLUMNS($A$3:M16),0) -> 7 | U17: 28 Days Later
A18: The Bridge on the River Kwai | B18: =VLOOKUP($A18,Table1[[#All],[Title]:[Oscar Wins]],COLUMNS($A$3:B17),0) -> 21095 | C18: =VLOOKUP($A18,Table1[[#All],[Title]:[Oscar Wins]],COLUMNS($A$3:C17),0) -> 161 | D18: =VLOOKUP($A18,Table1[[#All],[Title]:[Oscar Wins]],COLUMNS($A$3:D17),0) -> War | E18: =VLOOKUP($A18,Table1[[#All],[Title]:[Oscar Wins]],COLUMNS($A$3:E17),0) -> David Lean | F18: =VLOOKUP($A18,Table1[[#All],[Title]:[Oscar Wins]],COLUMNS($A$3:F17),0) -> Horizon Pictures | G18: =VLOOKUP($A18,Table1[[#All],[Title]:[Oscar Wins]],COLUMNS($A$3:G17),0) -> United Kingdom | H18: =VLOOKUP($A18,Table1[[#All],[Title]:[Oscar Wins]],COLUMNS($A$3:H17),0) -> English | I18: =VLOOKUP($A18,Table1[[#All],[Title]:[Oscar Wins]],COLUMNS($A$3:I17),0) -> U | J18: =ROUND(VLOOKUP($A18,Table1[[#All],[Title]:[Oscar Wins]],COLUMNS($A$3:J17),0)/1000000,2)&" M" -> 2.8 M | K18: =ROUND(VLOOKUP($A18,Table1[[#All],[Title]:[Oscar Wins]],COLUMNS($A$3:K17),0)/1000000,2)&" M" -> 30.6 M | L18: =VLOOKUP($A18,Table1[[#All],[Title]:[Oscar Wins]],COLUMNS($A$3:L17),0) -> 8 | M18: =VLOOKUP($A18,Table1[[#All],[Title]:[Oscar Wins]],COLUMNS($A$3:M17),0) -> 7 | U18: 28 Weeks Later
... A30: Terminator 2: Judgement Day | B30: =VLOOKUP($A30,Table1[[#All],[Title]:[Oscar Wins]],COLUMNS($A$3:B29),0) -> 33466 | C30: =VLOOKUP($A30,Table1[[#All],[Title]:[Oscar Wins]],COLUMNS($A$3:C29),0) -> 136 | D30: =VLOOKUP($A30,Table1[[#All],[Title]:[Oscar Wins]],COLUMNS($A$3:D29),0) -> Science Fiction | E30: =VLOOKUP($A30,Table1[[#All],[Title]:[Oscar Wins]],COLUMNS($A$3:E29),0) -> James Cameron | F30: =VLOOKUP($A30,Table1[[#All],[Title]:[Oscar Wins]],COLUMNS($A$3:F29),0) -> Carolco Pictures | G30: =VLOOKUP($A30,Table1[[#All],[Title]:[Oscar Wins]],COLUMNS($A$3:G29),0) -> United States | H30: =VLOOKUP($A30,Table1[[#All],[Title]:[Oscar Wins]],COLUMNS($A$3:H29),0) -> English | I30: =VLOOKUP($A30,Table1[[#All],[Title]:[Oscar Wins]],COLUMNS($A$3:I29),0) -> 15 | J30: =ROUND(VLOOKUP($A30,Table1[[#All],[Title]:[Oscar Wins]],COLUMNS($A$3:J29),0)/1000000,2)&" M" -> 100 M | K30: =ROUND(VLOOKUP($A30,Table1[[#All],[Title]:[Oscar Wins]],COLUMNS($A$3:K29),0)/1000000,2)&" M" -> 516.82 M | L30: =VLOOKUP($A30,Table1[[#All],[Title]:[Oscar Wins]],COLUMNS($A$3:L29),0) -> 4 | M30: =VLOOKUP($A30,Table1[[#All],[Title]:[Oscar Wins]],COLUMNS($A$3:M29),0) -> 6 | U30: A Field in England
U31: A Fistful of Dollars
U32: A Hard Day's Night
U33: A History of Violence
U34: A Knight's Tale
U35: A Life Less Ordinary
U36: A Million Ways to Die in the West
U37: A Place in the Sun
U38: A Prophet
U39: A Streetcar Named Desire
U40: A.I. Artificial Intelligence
U41: Abraham Lincoln: Vampire Hunter
U42: Air Force One
... U1053: Zulu

Sheet Hlookup
A1: Movie Name | B1: Release Date | C1: Run Time | D1: Genre | E1: Director | F1: Studio | G1: Country | H1: Language | I1: Certificate | J1: Budget | K1: Box Office | L1: Nominations | M1: Oscar Wins
A2: Titanic | B2: =HLOOKUP($A2,'Raw Data for Hlookup'!$2:$14,COLUMNS($A$1:B1),0) -> 35818 | C2: =HLOOKUP($A2,'Raw Data for Hlookup'!$2:$14,COLUMNS($A$1:C1),0) -> 194 | D2: =HLOOKUP($A2,'Raw Data for Hlookup'!$2:$14,COLUMNS($A$1:D1),0) -> Romance | E2: =HLOOKUP($A2,'Raw Data for Hlookup'!$2:$14,COLUMNS($A$1:E1),0) -> James Cameron | F2: =HLOOKUP($A2,'Raw Data for Hlookup'!$2:$14,COLUMNS($A$1:F1),0) -> 20th Century Fox | G2: =HLOOKUP($A2,'Raw Data for Hlookup'!$2:$14,COLUMNS($A$1:G1),0) -> United States | H2: =HLOOKUP($A2,'Raw Data for Hlookup'!$2:$14,COLUMNS($A$1:H1),0) -> English | I2: =HLOOKUP($A2,'Raw Data for Hlookup'!$2:$14,COLUMNS($A$1:I1),0) -> 12 | ... M2: =HLOOKUP($A2,'Raw Data for Hlookup'!$2:$14,COLUMNS($A$1:M1),0) -> 11
A3: The Lord of the Rings: Return of the King | B3: =HLOOKUP($A3,'Raw Data for Hlookup'!$2:$14,COLUMNS($A$1:B2),0) -> 37972 | C3: =HLOOKUP($A3,'Raw Data for Hlookup'!$2:$14,COLUMNS($A$1:C2),0) -> 201 | D3: =HLOOKUP($A3,'Raw Data for Hlookup'!$2:$14,COLUMNS($A$1:D2),0) -> Fantasy | E3: =HLOOKUP($A3,'Raw Data for Hlookup'!$2:$14,COLUMNS($A$1:E2),0) -> Peter Jackson | F3: =HLOOKUP($A3,'Raw Data for Hlookup'!$2:$14,COLUMNS($A$1:F2),0) -> WingNut Films | G3: =HLOOKUP($A3,'Raw Data for Hlookup'!$2:$14,COLUMNS($A$1:G2),0) -> New Zealand | H3: =HLOOKUP($A3,'Raw Data for Hlookup'!$2:$14,COLUMNS($A$1:H2),0) -> English | I3: =HLOOKUP($A3,'Raw Data for Hlookup'!$2:$14,COLUMNS($A$1:I2),0) -> 12A | ... M3: =HLOOKUP($A3,'Raw Data for Hlookup'!$2:$14,COLUMNS($A$1:M2),0) -> 11
A4: Ben-Hur | B4: =HLOOKUP($A4,'Raw Data for Hlookup'!$2:$14,COLUMNS($A$1:B3),0) -> 21872 | C4: =HLOOKUP($A4,'Raw Data for Hlookup'!$2:$14,COLUMNS($A$1:C3),0) -> 212 | D4: =HLOOKUP($A4,'Raw Data for Hlookup'!$2:$14,COLUMNS($A$1:D3),0) -> Drama | E4: =HLOOKUP($A4,'Raw Data for Hlookup'!$2:$14,COLUMNS($A$1:E3),0) -> William Wyler | F4: =HLOOKUP($A4,'Raw Data for Hlookup'!$2:$14,COLUMNS($A$1:F3),0) -> Metro-Goldwyn-Mayer | G4: =HLOOKUP($A4,'Raw Data for Hlookup'!$2:$14,COLUMNS($A$1:G3),0) -> United States | H4: =HLOOKUP($A4,'Raw Data for Hlookup'!$2:$14,COLUMNS($A$1:H3),0) -> English | I4: =HLOOKUP($A4,'Raw Data for Hlookup'!$2:$14,COLUMNS($A$1:I3),0) -> PG | ... M4: =HLOOKUP($A4,'Raw Data for Hlookup'!$2:$14,COLUMNS($A$1:M3),0) -> 11
A5: West Side Story | B5: =HLOOKUP($A5,'Raw Data for Hlookup'!$2:$14,COLUMNS($A$1:B4),0) -> 22572 | C5: =HLOOKUP($A5,'Raw Data for Hlookup'!$2:$14,COLUMNS($A$1:C4),0) -> 152 | D5: =HLOOKUP($A5,'Raw Data for Hlookup'!$2:$14,COLUMNS($A$1:D4),0) -> Musical | E5: =HLOOKUP($A5,'Raw Data for Hlookup'!$2:$14,COLUMNS($A$1:E4),0) -> Robert Wise | F5: =HLOOKUP($A5,'Raw Data for Hlookup'!$2:$14,COLUMNS($A$1:F4),0) -> The Mirisch Production Company | G5: =HLOOKUP($A5,'Raw Data for Hlookup'!$2:$14,COLUMNS($A$1:G4),0) -> United States | H5: =HLOOKUP($A5,'Raw Data for Hlookup'!$2:$14,COLUMNS($A$1:H4),0) -> English | I5: =HLOOKUP($A5,'Raw Data for Hlookup'!$2:$14,COLUMNS($A$1:I4),0) -> PG | ... M5: =HLOOKUP($A5,'Raw Data for Hlookup'!$2:$14,COLUMNS($A$1:M4),0) -> 10
A6: The English Patient | B6: =HLOOKUP($A6,'Raw Data for Hlookup'!$2:$14,COLUMNS($A$1:B5),0) -> 35384 | C6: =HLOOKUP($A6,'Raw Data for Hlookup'!$2:$14,COLUMNS($A$1:C5),0) -> 162 | D6: =HLOOKUP($A6,'Raw Data for Hlookup'!$2:$14,COLUMNS($A$1:D5),0) -> Romance | E6: =HLOOKUP($A6,'Raw Data for Hlookup'!$2:$14,COLUMNS($A$1:E5),0) -> Anthony Minghella | F6: =HLOOKUP($A6,'Raw Data for Hlookup'!$2:$14,COLUMNS($A$1:F5),0) -> Miramax Films | G6: =HLOOKUP($A6,'Raw Data for Hlookup'!$2:$14,COLUMNS($A$1:G5),0) -> United Kingdom | H6: =HLOOKUP($A6,'Raw Data for Hlookup'!$2:$14,COLUMNS($A$1:H5),0) -> English | I6: =HLOOKUP($A6,'Raw Data for Hlookup'!$2:$14,COLUMNS($A$1:I5),0) -> 15 | ... M6: =HLOOKUP($A6,'Raw Data for Hlookup'!$2:$14,COLUMNS($A$1:M5),0) -> 9
A7: On the Waterfront | B7: =HLOOKUP($A7,'Raw Data for Hlookup'!$2:$14,COLUMNS($A$1:B6),0) -> 19933 | C7: =HLOOKUP($A7,'Raw Data for Hlookup'!$2:$14,COLUMNS($A$1:C6),0) -> 108 | D7: =HLOOKUP($A7,'Raw Data for Hlookup'!$2:$14,COLUMNS($A$1:D6),0) -> Crime | E7: =HLOOKUP($A7,'Raw Data for Hlookup'!$2:$14,COLUMNS($A$1:E6),0) -> Elia Kazan | F7: =HLOOKUP($A7,'Raw Data for Hlookup'!$2:$14,COLUMNS($A$1:F6),0) -> Horizon Pictures | G7: =HLOOKUP($A7,'Raw Data for Hlookup'!$2:$14,COLUMNS($A$1:G6),0) -> United States | H7: =HLOOKUP($A7,'Raw Data for Hlookup'!$2:$14,COLUMNS($A$1:H6),0) -> English | I7: =HLOOKUP($A7,'Raw Data for Hlookup'!$2:$14,COLUMNS($A$1:I6),0) -> PG | ... M7: =HLOOKUP($A7,'Raw Data for Hlookup'!$2:$14,COLUMNS($A$1:M6),0) -> 8
A8: Gone with the Wind | B8: =HLOOKUP($A8,'Raw Data for Hlookup'!$2:$14,COLUMNS($A$1:B7),0) -> 14594 | C8: =HLOOKUP($A8,'Raw Data for Hlookup'!$2:$14,COLUMNS($A$1:C7),0) -> 221 | D8: =HLOOKUP($A8,'Raw Data for Hlookup'!$2:$14,COLUMNS($A$1:D7),0) -> Romance | E8: =HLOOKUP($A8,'Raw Data for Hlookup'!$2:$14,COLUMNS($A$1:E7),0) -> Victor Fleming | F8: =HLOOKUP($A8,'Raw Data for Hlookup'!$2:$14,COLUMNS($A$1:F7),0) -> Selznick International Pictures | G8: =HLOOKUP($A8,'Raw Data for Hlookup'!$2:$14,COLUMNS($A$1:G7),0) -> United States | H8: =HLOOKUP($A8,'Raw Data for Hlookup'!$2:$14,COLUMNS($A$1:H7),0) -> English | I8: =HLOOKUP($A8,'Raw Data for Hlookup'!$2:$14,COLUMNS($A$1:I7),0) -> PG | ... M8: =HLOOKUP($A8,'Raw Data for Hlookup'!$2:$14,COLUMNS($A$1:M7),0) -> 8
A9: Cabaret | B9: =HLOOKUP($A9,'Raw Data for Hlookup'!$2:$14,COLUMNS($A$1:B8),0) -> 26342 | C9: =HLOOKUP($A9,'Raw Data for Hlookup'!$2:$14,COLUMNS($A$1:C8),0) -> 124 | D9: =HLOOKUP($A9,'Raw Data for Hlookup'!$2:$14,COLUMNS($A$1:D8),0) -> Musical | E9: =HLOOKUP($A9,'Raw Data for Hlookup'!$2:$14,COLUMNS($A$1:E8),0) -> Bob Fosse | F9: =HLOOKUP($A9,'Raw Data for Hlookup'!$2:$14,COLUMNS($A$1:F8),0) -> Allied Artists | G9: =HLOOKUP($A9,'Raw Data for Hlookup'!$2:$14,COLUMNS($A$1:G8),0) -> United States | H9: =HLOOKUP($A9,'Raw Data for Hlookup'!$2:$14,COLUMNS($A$1:H8),0) -> English | I9: =HLOOKUP($A9,'Raw Data for Hlookup'!$2:$14,COLUMNS($A$1:I8),0) -> 15 | ... M9: =HLOOKUP($A9,'Raw Data for Hlookup'!$2:$14,COLUMNS($A$1:M8),0) -> 8
A10: Slumdog Millionaire | B10: =HLOOKUP($A10,'Raw Data for Hlookup'!$2:$14,COLUMNS($A$1:B9),0) -> 39690 | C10: =HLOOKUP($A10,'Raw Data for Hlookup'!$2:$14,COLUMNS($A$1:C9),0) -> 120 | D10: =HLOOKUP($A10,'Raw Data for Hlookup'!$2:$14,COLUMNS($A$1:D9),0) -> Drama | E10: =HLOOKUP($A10,'Raw Data for Hlookup'!$2:$14,COLUMNS($A$1:E9),0) -> Danny Boyle | F10: =HLOOKUP($A10,'Raw Data for Hlookup'!$2:$14,COLUMNS($A$1:F9),0) -> FilmFour Productions | G10: =HLOOKUP($A10,'Raw Data for Hlookup'!$2:$14,COLUMNS($A$1:G9),0) -> United Kingdom | H10: =HLOOKUP($A10,'Raw Data for Hlookup'!$2:$14,COLUMNS($A$1:H9),0) -> English | I10: =HLOOKUP($A10,'Raw Data for Hlookup'!$2:$14,COLUMNS($A$1:I9),0) -> 15 | ... M10: =HLOOKUP($A10,'Raw Data for Hlookup'!$2:$14,COLUMNS($A$1:M9),0) -> 8
A11: From Here to Eternity | B11: =HLOOKUP($A11,'Raw Data for Hlookup'!$2:$14,COLUMNS($A$1:B10),0) -> 19576 | C11: =HLOOKUP($A11,'Raw Data for Hlookup'!$2:$14,COLUMNS($A$1:C10),0) -> 118 | D11: =HLOOKUP($A11,'Raw Data for Hlookup'!$2:$14,COLUMNS($A$1:D10),0) -> Drama | E11: =HLOOKUP($A11,'Raw Data for Hlookup'!$2:$14,COLUMNS($A$1:E10),0) -> Fred Zinnemann | F11: =HLOOKUP($A11,'Raw Data for Hlookup'!$2:$14,COLUMNS($A$1:F10),0) -> Columbia Pictures | G11: =HLOOKUP($A11,'Raw Data for Hlookup'!$2:$14,COLUMNS($A$1:G10),0) -> United States | H11: =HLOOKUP($A11,'Raw Data for Hlookup'!$2:$14,COLUMNS($A$1:H10),0) -> English | I11: =HLOOKUP($A11,'Raw Data for Hlookup'!$2:$14,COLUMNS($A$1:I10),0) -> PG | ... M11: =HLOOKUP($A11,'Raw Data for Hlookup'!$2:$14,COLUMNS($A$1:M10),0) -> 8
A12: Gandhi | B12: =HLOOKUP($A12,'Raw Data for Hlookup'!$2:$14,COLUMNS($A$1:B11),0) -> 30287 | C12: =HLOOKUP($A12,'Raw Data for Hlookup'!$2:$14,COLUMNS($A$1:C11),0) -> 188 | D12: =HLOOKUP($A12,'Raw Data for Hlookup'!$2:$14,COLUMNS($A$1:D11),0) -> Biography | E12: =HLOOKUP($A12,'Raw Data for Hlookup'!$2:$14,COLUMNS($A$1:E11),0) -> Richard Attenborough | F12: =HLOOKUP($A12,'Raw Data for Hlookup'!$2:$14,COLUMNS($A$1:F11),0) -> Goldcrest Films | G12: =HLOOKUP($A12,'Raw Data for Hlookup'!$2:$14,COLUMNS($A$1:G11),0) -> United Kingdom | H12: =HLOOKUP($A12,'Raw Data for Hlookup'!$2:$14,COLUMNS($A$1:H11),0) -> English | I12: =HLOOKUP($A12,'Raw Data for Hlookup'!$2:$14,COLUMNS($A$1:I11),0) -> PG | ... M12: =HLOOKUP($A12,'Raw Data for Hlookup'!$2:$14,COLUMNS($A$1:M11),0) -> 8
A13: My Fair Lady | B13: =HLOOKUP($A13,'Raw Data for Hlookup'!$2:$14,COLUMNS($A$1:B12),0) -> 23690 | C13: =HLOOKUP($A13,'Raw Data for Hlookup'!$2:$14,COLUMNS($A$1:C12),0) -> 170 | D13: =HLOOKUP($A13,'Raw Data for Hlookup'!$2:$14,COLUMNS($A$1:D12),0) -> Musical | E13: =HLOOKUP($A13,'Raw Data for Hlookup'!$2:$14,COLUMNS($A$1:E12),0) -> George Cukor | F13: =HLOOKUP($A13,'Raw Data for Hlookup'!$2:$14,COLUMNS($A$1:F12),0) -> Warner Bros. Pictures | G13: =HLOOKUP($A13,'Raw Data for Hlookup'!$2:$14,COLUMNS($A$1:G12),0) -> United States | H13: =HLOOKUP($A13,'Raw Data for Hlookup'!$2:$14,COLUMNS($A$1:H12),0) -> English | I13: =HLOOKUP($A13,'Raw Data for Hlookup'!$2:$14,COLUMNS($A$1:I12),0) -> U | ... M13: =HLOOKUP($A13,'Raw Data for Hlookup'!$2:$14,COLUMNS($A$1:M12),0) -> 8
... A28: Terminator 2: Judgement Day | B28: =HLOOKUP($A28,'Raw Data for Hlookup'!$2:$14,COLUMNS($A$1:B27),0) -> 33466 | C28: =HLOOKUP($A28,'Raw Data for Hlookup'!$2:$14,COLUMNS($A$1:C27),0) -> 136 | D28: =HLOOKUP($A28,'Raw Data for Hlookup'!$2:$14,COLUMNS($A$1:D27),0) -> Science Fiction | E28: =HLOOKUP($A28,'Raw Data for Hlookup'!$2:$14,COLUMNS($A$1:E27),0) -> James Cameron | F28: =HLOOKUP($A28,'Raw Data for Hlookup'!$2:$14,COLUMNS($A$1:F27),0) -> Carolco Pictures | G28: =HLOOKUP($A28,'Raw Data for Hlookup'!$2:$14,COLUMNS($A$1:G27),0) -> United States | H28: =HLOOKUP($A28,'Raw Data for Hlookup'!$2:$14,COLUMNS($A$1:H27),0) -> English | I28: =HLOOKUP($A28,'Raw Data for Hlookup'!$2:$14,COLUMNS($A$1:I27),0) -> 15 | ... M28: =HLOOKUP($A28,'Raw Data for Hlookup'!$2:$14,COLUMNS($A$1:M27),0) -> 6

Sheet Raw Data for Hlookup
A1: ID | B1: 345 | C1: 441 | D1: 454 | E1: 1490 | F1: 1491 | G1: 1492 | H1: 1493 | I1: 1141 | J1: 357 | K1: 488 | L1: 205 | M1: 213 | N1: 226 | O1: 1138 | P1: 1229 | Q1: 1230 | R1: 1237 | S1: 1238 | T1: 1474 | U1: 72 | V1: 207 | W1: 231 | X1: 1205 | Y1: 1207 | Z1: 1220 | AA1: 1221 | AB1: 1301 | AC1: 1302 | AD1: 1303 | AE1: 1304 | AF1: 1309 | AG1: 1331 | AH1: 1365 | AI1: 223 | AJ1: 227 | AK1: 255 | AL1: 1462 | AM1: 1675 | AN1: 238 | AO1: 1167 | AP1: 1168 | AQ1: 1169 | AR1: 1170 | AS1: 1171 | AT1: 1195 | AU1: 1197 | AV1: 1209 | AW1: 1210 | AX1: 1228 | AY1: 1232 | AZ1: 1247 | BA1: 1248 | BB1: 1249 | BC1: 1250 | BD1: 1310 | BE1: 1239 | BF1: 1241 | BG1: 633 | BH1: 650 | BI1: 1377 | BJ1: 1378 | BK1: 260 | BL1: 262 | BM1: 263 | BN1: 598 | BO1: 1253 | BP1: 1269 | BQ1: 1270 | BR1: 1281 | BS1: 1287 | BT1: 1289 | BU1: 1298 | BV1: 1299 | BW1: 1359 | BX1: 3 | BY1: 59 | BZ1: 73 | CA1: 74 | CB1: 265 | CC1: 271 | CD1: 283 | CE1: 293 | CF1: 1399 | CG1: 253 | CH1: 1395 | CI1: 1322 | CJ1: 1323 | CK1: 1575 | CL1: 1579 | CM1: 1582 | CN1: 1242 | CO1: 1243 | CP1: 1245 | CQ1: 1246 | CR1: 11 | CS1: 18 | CT1: 22 | CU1: 31 | CV1: 35 | CW1: 38 | CX1: 51 | CY1: 61 | CZ1: 65 | DA1: 120 | DB1: 156 | DC1: 157 | DD1: 167 | DE1: 178 | DF1: 194 | DG1: 202 | DH1: 206 | DI1: 216 | DJ1: 219 | DK1: 220 | DL1: 221 | DM1: 222 | DN1: 228 | DO1: 233 | DP1: 236 | DQ1: 239 | DR1: 241 | DS1: 242 | DT1: 251 | DU1: 252 | DV1: 256 | DW1: 258 | DX1: 264 | DY1: 266 | DZ1: 291 | EA1: 300 | EB1: 311 | EC1: 312 | ED1: 321 | EE1: 327 | EF1: 334 | EG1: 336 | EH1: 339 | EI1: 346 | EJ1: 369 | EK1: 376 | EL1: 382 | EM1: 494 | EN1: 498 | EO1: 500 | EP1: 524 | EQ1: 531 | ER1: 544 | ES1: 548 | ET1: 588 | EU1: 589 | EV1: 609 | EW1: 614 | EX1: 615 | EY1: 639 | EZ1: 653 | FA1: 664 | FB1: 675 | FC1: 714 | FD1: 766 | FE1: 769 | FF1: 899 | FG1: 1125 | FH1: 1150 | FI1: 1151 | FJ1: 1154 | FK1: 1159 | FL1: 1161 | FM1: 1162 | FN1: 1164 | FO1: 1172 | FP1: 1173 | FQ1: 1219 | FR1: 1311 | FS1: 1314 | FT1: 1315 | FU1: 1316 | FV1: 1317 | FW1: 1319 | FX1: 1320 | FY1: 1326 | FZ1: 1327 | GA1: 1328 | GB1: 1330 | GC1: 1333 | GD1: 1334 | GE1: 1335 | GF1: 1336 | GG1: 1337 | GH1: 1371 | GI1: 1372 | GJ1: 1373 | GK1: 1374 | GL1: 1375 | GM1: 1376 | GN1: 1404 | GO1: 1415 | GP1: 1416 | GQ1: 1417 | GR1: 1418 | GS1: 1427 | GT1: 1429 | GU1: 1433 | GV1: 1456 | GW1: 1461 | GX1: 1472 | GY1: 1485 | GZ1: 1488 | HA1: 1505 | HB1: 1535 | HC1: 1542 | HD1: 1543 | HE1: 1546 | HF1: 1547 | HG1: 1557 | HH1: 1558 | HI1: 1560 | HJ1: 1561 | HK1: 1572 | HL1: 1599 | HM1: 1605 | HN1: 1606 | HO1: 1609 | HP1: 1610 | HQ1: 1612 | HR1: 1613 | HS1: 1620 | HT1: 1625 | HU1: 1644 | HV1: 1645 | HW1: 1646 | HX1: 1647 | HY1: 1650 | HZ1: 1653 | IA1: 1 | IB1: 2 | IC1: 5 | ID1: 6 | IE1: 7 | IF1: 8 | IG1: 9 | IH1: 10 | II1: 12 | IJ1: 13 | IK1: 14 | IL1: 15 | IM1: 16 | IN1: 17 | IO1: 19 | IP1: 20 | IQ1: 21 | IR1: 23 | IS1: 24 | IT1: 25 | IU1: 26 | IV1: 27 | IW1: 28 | IX1: 29 | IY1: 30 | IZ1: 32 | JA1: 33 | JB1: 34 | JC1: 36 | JD1: 37 | JE1: 39 | JF1: 40 | JG1: 41 | JH1: 42 | JI1: 43 | JJ1: 44 | JK1: 45 | JL1: 46 | JM1: 47 | JN1: 48 | JO1: 49 | JP1: 50 | JQ1: 52 | JR1: 53 | JS1: 54 | JT1: 55 | JU1: 56 | JV1: 57 | JW1: 58 | JX1: 60 | JY1: 62 | JZ1: 63 | KA1: 64 | KB1: 66 | KC1: 67 | KD1: 68 | KE1: 69 | KF1: 70 | KG1: 71 | KH1: 75 | KI1: 76 | KJ1: 77 | KK1: 78 | KL1: 79 | KM1: 80 | KN1: 81 | KO1: 82 | KP1: 83 | KQ1: 84 | KR1: 85 | KS1: 86 | KT1: 87 | KU1: 88 | KV1: 89 | KW1: 90 | KX1: 91 | KY1: 92 | KZ1: 93 | LA1: 94 | LB1: 95 | LC1: 96 | LD1: 97 | LE1: 98 | LF1: 99 | LG1: 100 | LH1: 101 | LI1: 102 | LJ1: 103 | LK1: 104 | LL1: 105 | LM1: 106 | LN1: 107 | LO1: 108 | LP1: 109 | LQ1: 110 | LR1: 111 | LS1: 112 | LT1: 113 | LU1: 114 | LV1: 115 | LW1: 116 | LX1: 117 | LY1: 118 | LZ1: 119 | MA1: 121 | MB1: 122 | MC1: 123 | MD1: 124 | ME1: 125 | MF1: 126 | MG1: 127 | MH1: 128 | MI1: 129 | MJ1: 130 | MK1: 131 | ML1: 132 | MM1: 133 | MN1: 134 | MO1: 135 | MP1: 136 | MQ1: 137 | MR1: 138 | MS1: 139 | MT1: 140 | MU1: 141 | MV1: 142 | MW1: 143 | MX1: 144 | MY1: 145 | MZ1: 146 | NA1: 147 | NB1: 148 | NC1: 149 | ND1: 150 | NE1: 151 | NF1: 152 | NG1: 153 | NH1: 154 | NI1: 155 | NJ1: 158 | NK1: 159 | NL1: 160 | NM1: 161 | NN1: 162 | NO1: 163 | NP1: 164 | NQ1: 165 | NR1: 166 | NS1: 168 | NT1: 169 | NU1: 170 | NV1: 171 | NW1: 172 | NX1: 173 | NY1: 174 | NZ1: 175 | OA1: 176 | OB1: 177 | OC1: 179 | OD1: 180 | OE1: 181 | OF1: 182 | OG1: 183 | OH1: 184 | OI1: 185 | OJ1: 186 | OK1: 187 | OL1: 188 | OM1: 189 | ON1: 190 | OO1: 191 | OP1: 192 | OQ1: 193 | OR1: 195 | OS1: 196 | OT1: 197 | OU1: 199 | OV1: 200 | OW1: 201 | OX1: 203 | OY1: 204 | OZ1: 208 | PA1: 209 | PB1: 210 | PC1: 211 | PD1: 212 | PE1: 214 | PF1: 215 | PG1: 217 | PH1: 218 | PI1: 224 | PJ1: 225 | PK1: 229 | PL1: 230 | PM1: 232 | PN1: 234 | PO1: 237 | PP1: 240 | PQ1: 243 | PR1: 244 | PS1: 245 | PT1: 246 | PU1: 249 | PV1: 250 | PW1: 254 | PX1: 257 | PY1: 259 | PZ1: 261 | QA1: 267 | QB1: 270 | QC1: 272 | QD1: 273 | QE1: 274 | QF1: 275 | QG1: 276 | QH1: 277 | QI1: 278 | QJ1: 279 | QK1: 280 | QL1: 281 | QM1: 282 | QN1: 284 | QO1: 285 | QP1: 286 | QQ1: 287 | QR1: 288 | QS1: 289 | QT1: 290 | QU1: 292 | QV1: 294 | QW1: 295 | QX1: 296 | QY1: 297 | QZ1: 298 | RA1: 299 | RB1: 301 | RC1: 302 | RD1: 303 | RE1: 304 | RF1: 305 | RG1: 306 | RH1: 307 | RI1: 308 | RJ1: 309 | RK1: 310 | RL1: 313 | RM1: 314 | RN1: 315 | RO1: 316 | RP1: 317 | RQ1: 318 | RR1: 319 | RS1: 320 | RT1: 322 | RU1: 323 | RV1: 324 | RW1: 325 | RX1: 326 | RY1: 328 | RZ1: 329 | SA1: 330 | SB1: 332 | SC1: 333 | SD1: 335 | SE1: 337 | SF1: 338 | SG1: 340 | SH1: 341 | SI1: 342 | SJ1: 343 | SK1: 344 | SL1: 347 | SM1: 348 | SN1: 349 | SO1: 350 | SP1: 351 | SQ1: 352 | SR1: 353 | SS1: 354 | ST1: 355 | SU1: 356 | SV1: 358 | SW1: 359 | SX1: 360 | SY1: 361 | SZ1: 362 | TA1: 363 | TB1: 364 | TC1: 365 | TD1: 366 | TE1: 367 | TF1: 368 | TG1: 370 | TH1: 371 | TI1: 372 | TJ1: 373 | TK1: 374 | TL1: 375 | TM1: 377 | TN1: 378 | TO1: 380 | TP1: 381 | TQ1: 383 | TR1: 384 | TS1: 385 | TT1: 386 | TU1: 387 | TV1: 388 | TW1: 389 | TX1: 390 | TY1: 391 | TZ1: 392 | UA1: 393 | UB1: 394 | UC1: 395 | UD1: 396 | UE1: 397 | UF1: 398 | UG1: 399 | UH1: 400 | UI1: 401 | UJ1: 403 | UK1: 404 | UL1: 405 | UM1: 406 | UN1: 407 | UO1: 408 | UP1: 409 | UQ1: 410 | UR1: 411 | US1: 412 | UT1: 413 | UU1: 414 | UV1: 415 | UW1: 416 | UX1: 417 | UY1: 418 | UZ1: 419 | VA1: 420 | VB1: 421 | VC1: 422 | VD1: 423 | VE1: 424 | VF1: 425 | VG1: 426 | VH1: 427 | VI1: 428 | VJ1: 430 | VK1: 431 | VL1: 432 | VM1: 433 | VN1: 434 | VO1: 435 | VP1: 436 | VQ1: 437 | VR1: 438 | VS1: 439 | VT1: 440 | VU1: 442 | VV1: 443 | VW1: 444 | VX1: 445 | VY1: 446 | VZ1: 447 | WA1: 448 | WB1: 449 | WC1: 450 | WD1: 451 | WE1: 452 | WF1: 453 | WG1: 455 | WH1: 456 | WI1: 458 | WJ1: 460 | WK1: 461 | WL1: 462 | WM1: 463 | WN1: 464 | WO1: 465 | WP1: 466 | WQ1: 468 | WR1: 469 | WS1: 470 | WT1: 472 | WU1: 473 | WV1: 474 | WW1: 475 | WX1: 476 | WY1: 477 | WZ1: 478 | XA1: 479 | XB1: 480 | XC1: 481 | XD1: 482 | XE1: 485 | XF1: 486 | XG1: 487 | XH1: 489 | XI1: 490 | XJ1: 492 | XK1: 495 | XL1: 497 | XM1: 501 | XN1: 502 | XO1: 503 | XP1: 504 | XQ1: 505 | XR1: 507 | XS1: 509 | XT1: 510 | XU1: 511 | XV1: 512 | XW1: 513 | XX1: 514 | XY1: 515 | XZ1: 516 | YA1: 517 | YB1: 518 | YC1: 519 | YD1: 522 | YE1: 523 | YF1: 525 | YG1: 526 | YH1: 527 | YI1: 529 | YJ1: 532 | YK1: 533 | YL1: 534 | YM1: 537 | YN1: 538 | YO1: 540 | YP1: 541 | YQ1: 542 | YR1: 543 | YS1: 545 | YT1: 546 | YU1: 547 | YV1: 553 | YW1: 554 | YX1: 556 | YY1: 557 | YZ1: 558 | ZA1: 559 | ZB1: 561 | ZC1: 563 | ZD1: 564 | ZE1: 565 | ZF1: 566 | ZG1: 570 | ZH1: 572 | ZI1: 573 | ZJ1: 576 | ZK1: 578 | ZL1: 582 | ZM1: 583 | ZN1: 584 | ZO1: 590 | ZP1: 591 | ZQ1: 593 | ZR1: 600 | ZS1: 601 | ZT1: 602 | ZU1: 605 | ZV1: 611 | ZW1: 612 | ZX1: 613 | ZY1: 617 | ZZ1: 618 | AAA1: 619 | AAB1: 621 | AAC1: 622 | AAD1: 627 | AAE1: 636 | AAF1: 638 | AAG1: 646 | AAH1: 648 | AAI1: 655 | AAJ1: 656 | AAK1: 657 | AAL1: 660 | AAM1: 662 | AAN1: 665 | AAO1: 669 | AAP1: 670 | AAQ1: 674 | AAR1: 676 | AAS1: 682 | AAT1: 684 | AAU1: 685 | AAV1: 687 | AAW1: 688 | AAX1: 691 | AAY1: 694 | AAZ1: 695 | ABA1: 696 | ABB1: 697 | ABC1: 704 | ABD1: 709 | ABE1: 710 | ABF1: 721 | ABG1: 722 | ABH1: 724 | ABI1: 726 | ABJ1: 727 | ABK1: 728 | ABL1: 731 | ABM1: 736 | ABN1: 737 | ABO1: 738 | ABP1: 744 | ABQ1: 753 | ABR1: 754 | ABS1: 755 | ABT1: 757 | ABU1: 761 | ABV1: 767 | ABW1: 774 | ABX1: 776 | ABY1: 779 | ABZ1: 781 | ACA1: 783 | ACB1: 784 | ACC1: 785 | ACD1: 796 | ACE1: 853 | ACF1: 858 | ACG1: 885 | ACH1: 887 | ACI1: 893 | ACJ1: 900 | ACK1: 913 | ACL1: 941 | ACM1: 972 | ACN1: 977 | ACO1: 982 | ACP1: 1063 | ACQ1: 1120 | ACR1: 1121 | ACS1: 1122 | ACT1: 1123 | ACU1: 1124 | ACV1: 1126 | ACW1: 1127 | ACX1: 1128 | ACY1: 1129 | ACZ1: 1130 | ADA1: 1131 | ADB1: 1132 | ADC1: 1133 | ADD1: 1134 | ADE1: 1135 | ADF1: 1136 | ADG1: 1137 | ADH1: 1139 | ADI1: 1140 | ADJ1: 1142 | ADK1: 1143 | ADL1: 1144 | ADM1: 1145 | ADN1: 1148 | ADO1: 1149 | ADP1: 1152 | ADQ1: 1156 | ADR1: 1157 | ADS1: 1158 | ADT1: 1163 | ADU1: 1165 | ADV1: 1166 | ADW1: 1185 | ADX1: 1203 | ADY1: 1204 | ADZ1: 1206 | AEA1: 1211 | AEB1: 1212 | AEC1: 1213 | AED1: 1214 | AEE1: 1215 | AEF1: 1216 | AEG1: 1217 | AEH1: 1218 | AEI1: 1233 | AEJ1: 1234 | AEK1: 1235 | AEL1: 1236 | AEM1: 1251 | AEN1: 1261 | AEO1: 1273 | AEP1: 1274 | AEQ1: 1275 | AER1: 1276 | AES1: 1277 | AET1: 1285 | AEU1: 1305 | AEV1: 1308 | AEW1: 1324 | AEX1: 1325 | AEY1: 1329 | AEZ1: 1332 | AFA1: 1338 | AFB1: 1339 | AFC1: 1340 | AFD1: 1341 | AFE1: 1342 | AFF1: 1343 | AFG1: 1344 | AFH1: 1345 | AFI1: 1346 | AFJ1: 1347 | AFK1: 1348 | AFL1: 1349 | AFM1: 1350 | AFN1: 1351 | AFO1: 1352 | AFP1: 1353 | AFQ1: 1354 | AFR1: 1355 | AFS1: 1356 | AFT1: 1357 | AFU1: 1358 | AFV1: 1360 | AFW1: 1361 | AFX1: 1362 | AFY1: 1363 | AFZ1: 1366 | AGA1: 1367 | AGB1: 1368 | AGC1: 1369 | AGD1: 1370 | AGE1: 1379 | AGF1: 1380 | AGG1: 1381 | AGH1: 1383 | AGI1: 1384 | AGJ1: 1385 | AGK1: 1386 | AGL1: 1387 | AGM1: 1388 | AGN1: 1389 | AGO1: 1390 | AGP1: 1391 | AGQ1: 1392 | AGR1: 1393 | AGS1: 1394 | AGT1: 1396 | AGU1: 1397 | AGV1: 1400 | AGW1: 1402 | AGX1: 1403 | AGY1: 1405 | AGZ1: 1406 | AHA1: 1407 | AHB1: 1408 | AHC1: 1409 | AHD1: 1410 | AHE1: 1411 | AHF1: 1412 | AHG1: 1413 | AHH1: 1414 | AHI1: 1419 | AHJ1: 1420 | AHK1: 1422 | AHL1: 1423 | AHM1: 1431 | AHN1: 1432 | AHO1: 1434 | AHP1: 1436 | AHQ1: 1437 | AHR1: 1438 | AHS1: 1439 | AHT1: 1440 | AHU1: 1441 | AHV1: 1442 | AHW1: 1443 | AHX1: 1444 | AHY1: 1445 | AHZ1: 1446 | AIA1: 1447 | AIB1: 1448 | AIC1: 1449 | AID1: 1450 | AIE1: 1451 | AIF1: 1452 | AIG1: 1453 | AIH1: 1454 | AII1: 1455 | AIJ1: 1457 | AIK1: 1458 | AIL1: 1459 | AIM1: 1460 | AIN1: 1463 | AIO1: 1464 | AIP1: 1465 | AIQ1: 1466 | AIR1: 1467 | AIS1: 1468 | AIT1: 1469 | AIU1: 1470 | AIV1: 1471 | AIW1: 1473 | AIX1: 1475 | AIY1: 1476 | AIZ1: 1478 | AJA1: 1479 | AJB1: 1480 | AJC1: 1481 | AJD1: 1482 | AJE1: 1483 | AJF1: 1484 | AJG1: 1486 | AJH1: 1487 | AJI1: 1489 | AJJ1: 1494 | AJK1: 1495 | AJL1: 1496 | AJM1: 1498 | AJN1: 1499 | AJO1: 1500 | AJP1: 1501 | AJQ1: 1503 | AJR1: 1504 | AJS1: 1507 | AJT1: 1508 | AJU1: 1509 | AJV1: 1510 | AJW1: 1511 | AJX1: 1512 | AJY1: 1513 | AJZ1: 1514 | AKA1: 1515 | AKB1: 1516 | AKC1: 1517 | AKD1: 1518 | AKE1: 1519 | AKF1: 1520 | AKG1: 1521 | AKH1: 1522 | AKI1: 1523 | AKJ1: 1524 | AKK1: 1525 | AKL1: 1526 | AKM1: 1527 | AKN1: 1528 | AKO1: 1529 | AKP1: 1530 | AKQ1: 1531 | AKR1: 1532 | AKS1: 1533 | AKT1: 1534 | AKU1: 1536 | AKV1: 1537 | AKW1: 1538 | AKX1: 1539 | AKY1: 1540 | AKZ1: 1541 | ALA1: 1545 | ALB1: 1548 | ALC1: 1550 | ALD1: 1551 | ALE1: 1552 | ALF1: 1553 | ALG1: 1554 | ALH1: 1555 | ALI1: 1556 | ALJ1: 1562 | ALK1: 1563 | ALL1: 1564 | ALM1: 1565 | ALN1: 1566 | ALO1: 1567 | ALP1: 1568 | ALQ1: 1569 | ALR1: 1570 | ALS1: 1571 | ALT1: 1573 | ALU1: 1574 | ALV1: 1577 | ALW1: 1580 | ALX1: 1581 | ALY1: 1583 | ALZ1: 1584 | AMA1: 1585 | AMB1: 1586 | AMC1: 1587 | AMD1: 1588 | AME1: 1589 | AMF1: 1590 | AMG1: 1591 | AMH1: 1592 | AMI1: 1593 | AMJ1: 1594 | AMK1: 1596 | AML1: 1597 | AMM1: 1600 | AMN1: 1601 | AMO1: 1602 | AMP1: 1603 | AMQ1: 1604 | AMR1: 1607 | AMS1: 1614 | AMT1: 1615 | AMU1: 1616 | AMV1: 1617 | AMW1: 1618 | AMX1: 1619 | AMY1: 1621 | AMZ1: 1622 | ANA1: 1624 | ANB1: 1626 | ANC1: 1627 | AND1: 1628 | ANE1: 1629 | ANF1: 1630 | ANG1: 1631 | ANH1: 1632 | ANI1: 1633 | ANJ1: 1634 | ANK1: 1635 | ANL1: 1636 | ANM1: 1637 | ANN1: 1638 | ANO1: 1639 | ANP1: 1640 | ANQ1: 1641 | ANR1: 1642 | ANS1: 1643 | ANT1: 1648 | ANU1: 1649 | ANV1: 1655 | ANW1: 1658 | ANX1: 1660 | ANY1: 1663 | ANZ1: 1664 | AOA1: 1666 | AOB1: 1667 | AOC1: 1668 | AOD1: 1670 | AOE1: 1671 | AOF1: 1672 | AOG1: 1673 | AOH1: 1674 | AOI1: 1676 | AOJ1: 1677
